Workbook

Sheet Summary
A1: RC Sample Tracker
A2: Exported RC sets that have never gone to the client: not emailed, and not staged in any week folder.
A3: Built 2026-09-15; cross-checked against both trackers (RC_Shipping_Tracker, RC_Shipped_Sets) and every delivered passage.
A5: Exported RC sets (unique IDs, all subfolders) | B5: 175
A6: Already with the client (in either tracker) | B6: 98
A7: Not sent (rows on Available RCs) | B7: =COUNTA('Available RCs'!$A:$A)-1 -> 77
A8: with 8 questions | B8: =COUNTIF('Available RCs'!$D:$D,8) -> 65
A9: with 6 questions (older format) | B9: =COUNTIF('Available RCs'!$D:$D,6) -> 12
A10: Samples sent so far | B10: =COUNTIF('Available RCs'!$E:$E,"Y") -> 0
A11: Still available for samples | B11: =B7-B10 -> 77
A13: Status | B13: Sets | C13: Sample Sent | D13: Still Available
A14: approved | B14: =COUNTIF('Available RCs'!$I:$I,$A14) -> 17 | C14: =COUNTIFS('Available RCs'!$I:$I,$A14,'Available RCs'!$E:$E,"Y") -> 0 | D14: =B14-C14 -> 17
A15: needs_review | B15: =COUNTIF('Available RCs'!$I:$I,$A15) -> 46 | C15: =COUNTIFS('Available RCs'!$I:$I,$A15,'Available RCs'!$E:$E,"Y") -> 0 | D15: =B15-C15 -> 46
A16: solver_dispute | B16: =COUNTIF('Available RCs'!$I:$I,$A16) -> 9 | C16: =COUNTIFS('Available RCs'!$I:$I,$A16,'Available RCs'!$E:$E,"Y") -> 0 | D16: =B16-C16 -> 9
A17: unrated | B17: =COUNTIF('Available RCs'!$I:$I,$A17) -> 1 | C17: =COUNTIFS('Available RCs'!$I:$I,$A17,'Available RCs'!$E:$E,"Y") -> 0 | D17: =B17-C17 -> 1
A18: blocked | B18: =COUNTIF('Available RCs'!$I:$I,$A18) -> 4 | C18: =COUNTIFS('Available RCs'!$I:$I,$A18,'Available RCs'!$E:$E,"Y") -> 0 | D18: =B18-C18 -> 4
A19: Total | B19: =SUM(B14:B18) -> 77 | C19: =SUM(C14:C18) -> 0 | D19: =SUM(D14:D18) -> 77
A21: Tier | B21: Sets | C21: Approved | D21: Sample Sent | E21: Still Available
A22: elite | B22: =COUNTIF('Available RCs'!$H:$H,$A22) -> 26 | C22: =COUNTIFS('Available RCs'!$H:$H,$A22,'Available RCs'!$I:$I,"approved") -> 8 | D22: =COUNTIFS('Available RCs'!$H:$H,$A22,'Available RCs'!$E:$E,"Y") -> 0 | E22: =B22-D22 -> 26
A23: hard | B23: =COUNTIF('Available RCs'!$H:$H,$A23) -> 33 | C23: =COUNTIFS('Available RCs'!$H:$H,$A23,'Available RCs'!$I:$I,"approved") -> 8 | D23: =COUNTIFS('Available RCs'!$H:$H,$A23,'Available RCs'!$E:$E,"Y") -> 0 | E23: =B23-D23 -> 33
A24: medium | B24: =COUNTIF('Available RCs'!$H:$H,$A24) -> 18 | C24: =COUNTIFS('Available RCs'!$H:$H,$A24,'Available RCs'!$I:$I,"approved") -> 1 | D24: =COUNTIFS('Available RCs'!$H:$H,$A24,'Available RCs'!$E:$E,"Y") -> 0 | E24: =B24-D24 -> 18
A25: Total | B25: =SUM(B22:B24) -> 77 | C25: =SUM(C22:C24) -> 17 | D25: =SUM(D22:D24) -> 0 | E25: =SUM(E22:E24) -> 77
A27: Genre | B27: Sets | C27: Approved | D27: Sample Sent | E27: Still Available
A28: Politics, Law & Policy | B28: =COUNTIF('Available RCs'!$B:$B,$A28) -> 12 | C28: =COUNTIFS('Available RCs'!$B:$B,$A28,'Available RCs'!$I:$I,"approved") -> 1 | D28: =COUNTIFS('Available RCs'!$B:$B,$A28,'Available RCs'!$E:$E,"Y") -> 0 | E28: =B28-D28 -> 12
A29: Literature & Criticism | B29: =COUNTIF('Available RCs'!$B:$B,$A29) -> 8 | C29: =COUNTIFS('Available RCs'!$B:$B,$A29,'Available RCs'!$I:$I,"approved") -> 0 | D29: =COUNTIFS('Available RCs'!$B:$B,$A29,'Available RCs'!$E:$E,"Y") -> 0 | E29: =B29-D29 -> 8
A30: History | B30: =COUNTIF('Available RCs'!$B:$B,$A30) -> 7 | C30: =COUNTIFS('Available RCs'!$B:$B,$A30,'Available RCs'!$I:$I,"approved") -> 1 | D30: =COUNTIFS('Available RCs'!$B:$B,$A30,'Available RCs'!$E:$E,"Y") -> 0 | E30: =B30-D30 -> 7
A31: Medicine & Health | B31: =COUNTIF('Available RCs'!$B:$B,$A31) -> 7 | C31: =COUNTIFS('Available RCs'!$B:$B,$A31,'Available RCs'!$I:$I,"approved") -> 0 | D31: =COUNTIFS('Available RCs'!$B:$B,$A31,'Available RCs'!$E:$E,"Y") -> 0 | E31: =B31-D31 -> 7
A32: Economics & Business | B32: =COUNTIF('Available RCs'!$B:$B,$A32) -> 6 | C32: =COUNTIFS('Available RCs'!$B:$B,$A32,'Available RCs'!$I:$I,"approved") -> 3 | D32: =COUNTIFS('Available RCs'!$B:$B,$A32,'Available RCs'!$E:$E,"Y") -> 0 | E32: =B32-D32 -> 6
A33: Arts, Music & Film | B33: =COUNTIF('Available RCs'!$B:$B,$A33) -> 5 | C33: =COUNTIFS('Available RCs'!$B:$B,$A33,'Available RCs'!$I:$I,"approved") -> 3 | D33: =COUNTIFS('Available RCs'!$B:$B,$A33,'Available RCs'!$E:$E,"Y") -> 0 | E33: =B33-D33 -> 5
A34: Language & Linguistics | B34: =COUNTIF('Available RCs'!$B:$B,$A34) -> 5 | C34: =COUNTIFS('Available RCs'!$B:$B,$A34,'Available RCs'!$I:$I,"approved") -> 2 | D34: =COUNTIFS('Available RCs'!$B:$B,$A34,'Available RCs'!$E:$E,"Y") -> 0 | E34: =B34-D34 -> 5
A35: Philosophy & Ethics | B35: =COUNTIF('Available RCs'!$B:$B,$A35) -> 5 | C35: =COUNTIFS('Available RCs'!$B:$B,$A35,'Available RCs'!$I:$I,"approved") -> 1 | D35: =COUNTIFS('Available RCs'!$B:$B,$A35,'Available RCs'!$E:$E,"Y") -> 0 | E35: =B35-D35 -> 5
A36: Science & Technology | B36: =COUNTIF('Available RCs'!$B:$B,$A36) -> 5 | C36: =COUNTIFS('Available RCs'!$B:$B,$A36,'Available RCs'!$I:$I,"approved") -> 1 | D36: =COUNTIFS('Available RCs'!$B:$B,$A36,'Available RCs'!$E:$E,"Y") -> 0 | E36: =B36-D36 -> 5
A37: Sociology & Culture | B37: =COUNTIF('Available RCs'!$B:$B,$A37) -> 5 | C37: =COUNTIFS('Available RCs'!$B:$B,$A37,'Available RCs'!$I:$I,"approved") -> 2 | D37: =COUNTIFS('Available RCs'!$B:$B,$A37,'Available RCs'!$E:$E,"Y") -> 0 | E37: =B37-D37 -> 5
A38: Anthropology & Archaeology | B38: =COUNTIF('Available RCs'!$B:$B,$A38) -> 4 | C38: =COUNTIFS('Available RCs'!$B:$B,$A38,'Available RCs'!$I:$I,"approved") -> 0 | D38: =COUNTIFS('Available RCs'!$B:$B,$A38,'Available RCs'!$E:$E,"Y") -> 0 | E38: =B38-D38 -> 4
A39: Psychology | B39: =COUNTIF('Available RCs'!$B:$B,$A39) -> 4 | C39: =COUNTIFS('Available RCs'!$B:$B,$A39,'Available RCs'!$I:$I,"approved") -> 2 | D39: =COUNTIFS('Available RCs'!$B:$B,$A39,'Available RCs'!$E:$E,"Y") -> 0 | E39: =B39-D39 -> 4
... A41: Education | B41: =COUNTIF('Available RCs'!$B:$B,$A41) -> 1 | C41: =COUNTIFS('Available RCs'!$B:$B,$A41,'Available RCs'!$I:$I,"approved") -> 1 | D41: =COUNTIFS('Available RCs'!$B:$B,$A41,'Available RCs'!$E:$E,"Y") -> 0 | E41: =B41-D41 -> 1
A42: Total | B42: =SUM(B28:B41) -> 77 | C42: =SUM(C28:C41) -> 17 | D42: =SUM(D28:D41) -> 0 | E42: =SUM(E28:E41) -> 77
A44: HOW TO USE
A45: Edit only the yellow columns on 'Available RCs': Sample Sent (Y/N), Sent To, Sent On.
A46: Example: Y | <institute name> | 2026-09-16. The counts above update as you mark Y.
...

Sheet Available RCs
A1: RC ID | B1: Genre | C1: Passage Length (words) | D1: No. of Questions | E1: Sample Sent (Y/N) | F1: Sent To | G1: Sent On | H1: Tier | I1: Status | J1: Notes | K1: File | L1: Sample Pack
A2: RC-ELITE-260904-0074 | B2: Arts, Music & Film | C2: 545 | D2: 8 | E2: N | H2: elite | I2: approved | K2: exported_rc_sets/RC-ELITE-260904-0074.txt
A3: RC-ELITE-260822-0057 | B3: Sociology & Culture | C3: 535 | D3: 8 | E3: N | H3: elite | I3: approved | J3: 2 exported versions; File is the preferred one | K3: exported_rc_sets/RC-ELITE-260822-0057.txt | L3: Pack 4
A4: RC-HARD-260822-0063 | B4: Arts, Music & Film | C4: 532 | D4: 8 | E4: N | H4: hard | I4: approved | K4: exported_rc_sets/RC-HARD-260822-0063.txt | L4: Pack 4
A5: RC-HARD-260811-0046 | B5: Economics & Business | C5: 512 | D5: 8 | E5: N | H5: hard | I5: approved | J5: 2 exported versions; File is the preferred one | K5: exported_rc_sets/RC-HARD-260811-0046.txt | L5: Pack 1
A6: RC-HARD-260912-0094 | B6: Economics & Business | C6: 538 | D6: 8 | E6: N | H6: hard | I6: approved | K6: exported_rc_sets/RC-HARD-260912-0094.txt | L6: Pack 3
A7: RC-HARD-260912-0091 | B7: History | C7: 548 | D7: 8 | E7: N | H7: hard | I7: approved | K7: exported_rc_sets/RC-HARD-260912-0091.txt | L7: Pack 2
A8: RC-ELITE-260711-0023 | B8: Economics & Business | C8: 532 | D8: 6 | E8: N | H8: elite | I8: approved | J8: 6 questions (older format) | K8: exported_rc_sets/RC-ELITE-260711-0023.txt
A9: RC_E_0705_7 | B9: Philosophy & Ethics | C9: 573 | D9: 6 | E9: N | H9: elite | I9: approved | J9: Legacy July set, not in the engine DB; 6 questions (older format) | K9: exported_rc_sets/RC_E_0705_7.txt
A10: RC-ELITE-260707-0022 | B10: Psychology | C10: 575 | D10: 6 | E10: N | H10: elite | I10: approved | J10: 6 questions (older format) | K10: exported_rc_sets/RC-ELITE-260707-0022.txt
A11: RC-HARD-260726-0022 | B11: Education | C11: 518 | D11: 6 | E11: N | H11: hard | I11: approved | J11: 6 questions (older format) | K11: exported_rc_sets/RC-HARD-260726-0022.txt
A12: RC-HARD-260726-0023 | B12: Language & Linguistics | C12: 536 | D12: 6 | E12: N | H12: hard | I12: approved | J12: 6 questions (older format) | K12: exported_rc_sets/RC-HARD-260726-0023.txt
A13: RC-HARD-260726-0024 | B13: Psychology | C13: 524 | D13: 6 | E13: N | H13: hard | I13: approved | J13: 6 questions (older format) | K13: exported_rc_sets/RC-HARD-260726-0024.txt
A14: RC-HARD-260726-0015 | B14: Sociology & Culture | C14: 501 | D14: 6 | E14: N | H14: hard | I14: approved | J14: 6 questions (older format) | K14: exported_rc_sets/RC-HARD-260726-0015.txt
A15: RC-ELITE-260914-0086 | B15: Language & Linguistics | C15: 538 | D15: 8 | E15: N | H15: elite | I15: approved | J15: Exported only to flagged_similar (novelty-flagged) | K15: exported_rc_sets/flagged_similar/RC-ELITE-260914-0086.txt | L15: Pack 2
A16: RC-ELITE-260905-0075 | B16: Politics, Law & Policy | C16: 549 | D16: 8 | E16: N | H16: elite | I16: approved | J16: Exported only to flagged_similar (novelty-flagged) | K16: exported_rc_sets/flagged_similar/RC-ELITE-260905-0075.txt
A17: RC-ELITE-260905-0077 | B17: Science & Technology | C17: 528 | D17: 8 | E17: N | H17: elite | I17: approved | J17: Exported only to flagged_similar (novelty-flagged) | K17: exported_rc_sets/flagged_similar/RC-ELITE-260905-0077.txt | L17: Pack 3
A18: RC-MEDIUM-260912-0068 | B18: Arts, Music & Film | C18: 543 | D18: 8 | E18: N | H18: medium | I18: approved | J18: Exported only to flagged_similar (novelty-flagged) | K18: exported_rc_sets/flagged_similar/RC-MEDIUM-260912-0068.txt | L18: Pack 2
A19: RC-ELITE-260822-0060 | B19: Arts, Music & Film | C19: 564 | D19: 8 | E19: N | H19: elite | I19: needs_review | J19: 4 exported versions; File is the preferred one | K19: exported_rc_sets/post_housevoice_fix/RC-ELITE-260822-0060.txt
A20: RC-ELITE-260811-0038 | B20: History | C20: 519 | D20: 8 | E20: N | H20: elite | I20: needs_review | J20: 2 exported versions; File is the preferred one | K20: exported_rc_sets/RC-ELITE-260811-0038.txt
A21: RC-ELITE-260905-0076 | B21: History | C21: 536 | D21: 8 | E21: N | H21: elite | I21: needs_review | K21: exported_rc_sets/RC-ELITE-260905-0076.txt
A22: RC-ELITE-260810-0035 | B22: Life Sciences & Environment | C22: 564 | D22: 8 | E22: N | H22: elite | I22: needs_review | J22: 2 exported versions; File is the preferred one | K22: exported_rc_sets/RC-ELITE-260810-0035.txt
A23: RC-ELITE-260907-0083 | B23: Medicine & Health | C23: 578 | D23: 8 | E23: N | H23: elite | I23: needs_review | K23: exported_rc_sets/RC-ELITE-260907-0083.txt
A24: RC-ELITE-260822-0062 | B24: Philosophy & Ethics | C24: 525 | D24: 8 | E24: N | H24: elite | I24: needs_review | K24: exported_rc_sets/RC-ELITE-260822-0062.txt
A25: RC-ELITE-260822-0059 | B25: Politics, Law & Policy | C25: 531 | D25: 8 | E25: N | H25: elite | I25: needs_review | J25: 3 exported versions; File is the preferred one | K25: exported_rc_sets/post_housevoice_fix/RC-ELITE-260822-0059.txt
A26: RC-ELITE-260907-0082 | B26: Politics, Law & Policy | C26: 550 | D26: 8 | E26: N | H26: elite | I26: needs_review | K26: exported_rc_sets/RC-ELITE-260907-0082.txt
A27: RC-ELITE-260821-0050 | B27: Psychology | C27: 533 | D27: 8 | E27: N | H27: elite | I27: needs_review | J27: 3 exported versions; File is the preferred one | K27: exported_rc_sets/RC-ELITE-260821-0050.txt | L27: Pack 1
A28: RC-ELITE-260912-0085 | B28: Science & Technology | C28: 572 | D28: 8 | E28: N | H28: elite | I28: needs_review | K28: exported_rc_sets/RC-ELITE-260912-0085.txt
A29: RC-HARD-260905-0082 | B29: Anthropology & Archaeology | C29: 549 | D29: 8 | E29: N | H29: hard | I29: needs_review | K29: exported_rc_sets/RC-HARD-260905-0082.txt
A30: RC-HARD-260905-0085 | B30: Economics & Business | C30: 521 | D30: 8 | E30: N | H30: hard | I30: needs_review | K30: exported_rc_sets/RC-HARD-260905-0085.txt
A31: RC-HARD-260810-0034 | B31: History | C31: 548 | D31: 8 | E31: N | H31: hard | I31: needs_review | J31: 2 exported versions; File is the preferred one | K31: exported_rc_sets/RC-HARD-260810-0034.txt
A32: RC-HARD-260819-0050 | B32: Language & Linguistics | C32: 533 | D32: 8 | E32: N | H32: hard | I32: needs_review | J32: 2 exported versions; File is the preferred one | K32: exported_rc_sets/RC-HARD-260819-0050.txt
A33: RC-HARD-260811-0035 | B33: Medicine & Health | C33: 516 | D33: 8 | E33: N | H33: hard | I33: needs_review | J33: 2 exported versions; File is the preferred one | K33: exported_rc_sets/RC-HARD-260811-0035.txt
A34: RC-HARD-260901-0073 | B34: Medicine & Health | C34: 540 | D34: 8 | E34: N | H34: hard | I34: needs_review | J34: 2 exported versions; File is the preferred one | K34: exported_rc_sets/2026-09-01-0901-v2/RC-HARD-260901-0073.txt
A35: RC-HARD-260901-0074 | B35: Medicine & Health | C35: 545 | D35: 8 | E35: N | H35: hard | I35: needs_review | J35: 2 exported versions; File is the preferred one | K35: exported_rc_sets/2026-09-01-0901-v2/RC-HARD-260901-0074.txt
A36: RC-HARD-260822-0061 | B36: Politics, Law & Policy | C36: 503 | D36: 8 | E36: N | H36: hard | I36: needs_review | J36: 4 exported versions; File is the preferred one | K36: exported_rc_sets/post_housevoice_fix/RC-HARD-260822-0061.txt
A37: RC-HARD-260914-0096 | B37: Politics, Law & Policy | C37: 551 | D37: 8 | E37: N | H37: hard | I37: needs_review | K37: exported_rc_sets/RC-HARD-260914-0096.txt
A38: RC-HARD-260914-0098 | B38: Politics, Law & Policy | C38: 502 | D38: 8 | E38: N | H38: hard | I38: needs_review | K38: exported_rc_sets/RC-HARD-260914-0098.txt
A39: RC-HARD-260907-0086 | B39: Science & Technology | C39: 550 | D39: 8 | E39: N | H39: hard | I39: needs_review | K39: exported_rc_sets/RC-HARD-260907-0086.txt
A40: RC-HARD-260901-0077 | B40: Sociology & Culture | C40: 551 | D40: 8 | E40: N | H40: hard | I40: needs_review | K40: exported_rc_sets/RC-HARD-260901-0077.txt
...
